<?xml version="1.0"?>
<robot xmlns:xacro="http://www.ros.org/wiki/xacro" >

    <xacro:include filename="inertial_macros.xacro"/>

    <material name="white"><color rgba="1 1 1 1" /></material>
    <material name="blue"><color rgba="0.2 0.2 1 1"/></material>
    <material name="black"><color rgba="0 0 0 1"/></material>

    <!-- BASE LINK -->
    <link name="base_link"></link>

    <!-- CHASSIS LINK -->
    <joint name="chassis_joint" type="fixed">
        <parent link="base_link"/>
        <child link="chassis"/>
        <origin xyz="-0.3 0 0"/>
    </joint>

    <link name="chassis">
        <visual>
            <origin xyz="0.3 0 0.075"/>
            <geometry><box size="0.6 0.3 0.15"/></geometry>
            <material name="white"/>
        </visual>
        <collision>
            <origin xyz="0.3 0 0.075"/>
            <geometry><box size="0.6 0.3 0.15"/></geometry>
        </collision>
        <xacro:inertial_box mass="1.0" x="0.6" y="0.3" z="0.15">
            <origin xyz="0.3 0 0.075" rpy="0 0 0"/>
        </xacro:inertial_box>
    </link>

    <gazebo reference="chassis">
        <material>Gazebo/White</material>
    </gazebo>
    
    <!-- WHEEL MACRO -->
    <xacro:macro name="wheel" params="prefix y_reflect x_offset">
        <joint name="${prefix}_wheel_joint" type="continuous">
            <parent link="base_link"/>
            <child link="${prefix}_wheel"/>
            <origin xyz="${x_offset} ${y_reflect * 0.175} 0" rpy="${y_reflect * pi/2} 0 0" />
            <axis xyz="0 0 ${-y_reflect}"/>
        </joint>

        <link name="${prefix}_wheel">
            <visual>
                <geometry><cylinder radius="0.05" length="0.04"/></geometry>
                <material name="blue"/>
            </visual>
            <collision>
                <geometry><cylinder radius="0.05" length="0.04"/></geometry>
            </collision>
            <xacro:inertial_cylinder mass="0.1" length="0.04" radius="0.05">
                <origin xyz="0 0 0" rpy="0 0 0"/>
            </xacro:inertial_cylinder>
        </link>
    </xacro:macro>

    <xacro:wheel prefix="left_front"  y_reflect="1"  x_offset="0.2"/>
    <xacro:wheel prefix="left_middle" y_reflect="1"  x_offset="0.0"/>
    <xacro:wheel prefix="left_back"   y_reflect="1"  x_offset="-0.2"/>
    <xacro:wheel prefix="right_front"  y_reflect="-1" x_offset="0.2"/>
    <xacro:wheel prefix="right_middle" y_reflect="-1" x_offset="0.0"/>
    <xacro:wheel prefix="right_back"   y_reflect="-1" x_offset="-0.2"/>

</robot>